2023-12-30 08:00:55,348 INFO    StreamThr :287688 [internal.py:wandb_internal():86] W&B internal server running at pid: 287688, started at: 2023-12-30 08:00:55.348321
2023-12-30 08:00:55,349 DEBUG   HandlerThread:287688 [handler.py:handle_request():144] handle_request: status
2023-12-30 08:00:55,351 INFO    WriterThread:287688 [datastore.py:open_for_write():85] open: /home/mib07150/git/sapient/KataBasicFlax/wandb/run-20231230_080055-gedhs1l7/run-gedhs1l7.wandb
2023-12-30 08:00:55,351 DEBUG   SenderThread:287688 [sender.py:send():375] send: header
2023-12-30 08:00:55,352 DEBUG   SenderThread:287688 [sender.py:send():375] send: run
2023-12-30 08:00:58,484 DEBUG   HandlerThread:287688 [handler.py:handle_request():144] handle_request: status_report
2023-12-30 08:00:58,886 INFO    SenderThread:287688 [retry.py:__call__():172] Retry attempt failed:
Traceback (most recent call last):
  File "/home/mib07150/prog/miniconda3/envs/py311/lib/python3.11/site-packages/urllib3/connection.py", line 174, in _new_conn
    conn = connection.create_connection(
           ^^^^^^^^^^^^^^^^^^^^^^^^^^^^^
  File "/home/mib07150/prog/miniconda3/envs/py311/lib/python3.11/site-packages/urllib3/util/connection.py", line 95, in create_connection
    raise err
  File "/home/mib07150/prog/miniconda3/envs/py311/lib/python3.11/site-packages/urllib3/util/connection.py", line 85, in create_connection
    sock.connect(sa)
ConnectionRefusedError: [Errno 111] Connection refused

During handling of the above exception, another exception occurred:

Traceback (most recent call last):
  File "/home/mib07150/prog/miniconda3/envs/py311/lib/python3.11/site-packages/urllib3/connectionpool.py", line 703, in urlopen
    httplib_response = self._make_request(
                       ^^^^^^^^^^^^^^^^^^^
  File "/home/mib07150/prog/miniconda3/envs/py311/lib/python3.11/site-packages/urllib3/connectionpool.py", line 398, in _make_request
    conn.request(method, url, **httplib_request_kw)
  File "/home/mib07150/prog/miniconda3/envs/py311/lib/python3.11/site-packages/urllib3/connection.py", line 239, in request
    super(HTTPConnection, self).request(method, url, body=body, headers=headers)
  File "/home/mib07150/prog/miniconda3/envs/py311/lib/python3.11/http/client.py", line 1282, in request
    self._send_request(method, url, body, headers, encode_chunked)
  File "/home/mib07150/prog/miniconda3/envs/py311/lib/python3.11/http/client.py", line 1328, in _send_request
    self.endheaders(body, encode_chunked=encode_chunked)
  File "/home/mib07150/prog/miniconda3/envs/py311/lib/python3.11/http/client.py", line 1277, in endheaders
    self._send_output(message_body, encode_chunked=encode_chunked)
  File "/home/mib07150/prog/miniconda3/envs/py311/lib/python3.11/http/client.py", line 1037, in _send_output
    self.send(msg)
  File "/home/mib07150/prog/miniconda3/envs/py311/lib/python3.11/http/client.py", line 975, in send
    self.connect()
  File "/home/mib07150/prog/miniconda3/envs/py311/lib/python3.11/site-packages/urllib3/connection.py", line 205, in connect
    conn = self._new_conn()
           ^^^^^^^^^^^^^^^^
  File "/home/mib07150/prog/miniconda3/envs/py311/lib/python3.11/site-packages/urllib3/connection.py", line 186, in _new_conn
    raise NewConnectionError(
urllib3.exceptions.NewConnectionError: <urllib3.connection.HTTPConnection object at 0x7f41f3813510>: Failed to establish a new connection: [Errno 111] Connection refused

During handling of the above exception, another exception occurred:

Traceback (most recent call last):
  File "/home/mib07150/prog/miniconda3/envs/py311/lib/python3.11/site-packages/requests/adapters.py", line 486, in send
    resp = conn.urlopen(
           ^^^^^^^^^^^^^
  File "/home/mib07150/prog/miniconda3/envs/py311/lib/python3.11/site-packages/urllib3/connectionpool.py", line 787, in urlopen
    retries = retries.increment(
              ^^^^^^^^^^^^^^^^^^
  File "/home/mib07150/prog/miniconda3/envs/py311/lib/python3.11/site-packages/urllib3/util/retry.py", line 592, in increment
    raise MaxRetryError(_pool, url, error or ResponseError(cause))
urllib3.exceptions.MaxRetryError: HTTPConnectionPool(host='localhost', port=8083): Max retries exceeded with url: /graphql (Caused by NewConnectionError('<urllib3.connection.HTTPConnection object at 0x7f41f3813510>: Failed to establish a new connection: [Errno 111] Connection refused'))

During handling of the above exception, another exception occurred:

Traceback (most recent call last):
  File "/home/mib07150/prog/miniconda3/envs/py311/lib/python3.11/site-packages/wandb/sdk/lib/retry.py", line 131, in __call__
    result = self._call_fn(*args, **kwargs)
             ^^^^^^^^^^^^^^^^^^^^^^^^^^^^^^
  File "/home/mib07150/prog/miniconda3/envs/py311/lib/python3.11/site-packages/wandb/sdk/internal/internal_api.py", line 285, in execute
    return self.client.execute(*args, **kwargs)  # type: ignore
           ^^^^^^^^^^^^^^^^^^^^^^^^^^^^^^^^^^^^
  File "/home/mib07150/prog/miniconda3/envs/py311/lib/python3.11/site-packages/wandb/vendor/gql-0.2.0/wandb_gql/client.py", line 52, in execute
    result = self._get_result(document, *args, **kwargs)
             ^^^^^^^^^^^^^^^^^^^^^^^^^^^^^^^^^^^^^^^^^^^
  File "/home/mib07150/prog/miniconda3/envs/py311/lib/python3.11/site-packages/wandb/vendor/gql-0.2.0/wandb_gql/client.py", line 60, in _get_result
    return self.transport.execute(document, *args, **kwargs)
           ^^^^^^^^^^^^^^^^^^^^^^^^^^^^^^^^^^^^^^^^^^^^^^^^^
  File "/home/mib07150/prog/miniconda3/envs/py311/lib/python3.11/site-packages/wandb/sdk/lib/gql_request.py", line 55, in execute
    request = self.session.post(self.url, **post_args)
              ^^^^^^^^^^^^^^^^^^^^^^^^^^^^^^^^^^^^^^^^
  File "/home/mib07150/prog/miniconda3/envs/py311/lib/python3.11/site-packages/requests/sessions.py", line 637, in post
    return self.request("POST", url, data=data, json=json, **kwargs)
           ^^^^^^^^^^^^^^^^^^^^^^^^^^^^^^^^^^^^^^^^^^^^^^^^^^^^^^^^^
  File "/home/mib07150/prog/miniconda3/envs/py311/lib/python3.11/site-packages/requests/sessions.py", line 589, in request
    resp = self.send(prep, **send_kwargs)
           ^^^^^^^^^^^^^^^^^^^^^^^^^^^^^^
  File "/home/mib07150/prog/miniconda3/envs/py311/lib/python3.11/site-packages/requests/sessions.py", line 703, in send
    r = adapter.send(request, **kwargs)
        ^^^^^^^^^^^^^^^^^^^^^^^^^^^^^^^
  File "/home/mib07150/prog/miniconda3/envs/py311/lib/python3.11/site-packages/requests/adapters.py", line 519, in send
    raise ConnectionError(e, request=request)
requests.exceptions.ConnectionError: HTTPConnectionPool(host='localhost', port=8083): Max retries exceeded with url: /graphql (Caused by NewConnectionError('<urllib3.connection.HTTPConnection object at 0x7f41f3813510>: Failed to establish a new connection: [Errno 111] Connection refused'))
2023-12-30 08:00:59,202 DEBUG   HandlerThread:287688 [handler.py:handle_request():144] handle_request: status_report
2023-12-30 08:00:59,534 DEBUG   HandlerThread:287688 [handler.py:handle_request():144] handle_request: status_report
2023-12-30 08:01:00,355 DEBUG   HandlerThread:287688 [handler.py:handle_request():144] handle_request: keepalive
2023-12-30 08:01:03,485 DEBUG   HandlerThread:287688 [handler.py:handle_request():144] handle_request: status_report
2023-12-30 08:01:04,202 DEBUG   HandlerThread:287688 [handler.py:handle_request():144] handle_request: status_report
2023-12-30 08:01:04,535 DEBUG   HandlerThread:287688 [handler.py:handle_request():144] handle_request: status_report
2023-12-30 08:01:05,356 DEBUG   HandlerThread:287688 [handler.py:handle_request():144] handle_request: keepalive
2023-12-30 08:01:08,486 DEBUG   HandlerThread:287688 [handler.py:handle_request():144] handle_request: status_report
2023-12-30 08:01:09,203 DEBUG   HandlerThread:287688 [handler.py:handle_request():144] handle_request: status_report
2023-12-30 08:01:09,535 DEBUG   HandlerThread:287688 [handler.py:handle_request():144] handle_request: status_report
2023-12-30 08:01:11,805 DEBUG   HandlerThread:287688 [handler.py:handle_request():144] handle_request: shutdown
2023-12-30 08:01:11,805 INFO    HandlerThread:287688 [handler.py:finish():845] shutting down handler
2023-12-30 08:01:12,536 INFO    SenderThread:287688 [sender.py:finish():1550] shutting down sender
2023-12-30 08:01:12,536 INFO    WriterThread:287688 [datastore.py:close():298] close: /home/mib07150/git/sapient/KataBasicFlax/wandb/run-20231230_075914-4cw7go9l/run-4cw7go9l.wandb
